<p>使用来自 <code>finally</code> 块的<code>return</code>, <code>break</code>, <code>throw</code>, 和 <code>continue</code>覆写来自挂起的<code>try</code> 和 <code>catch</code> 块的类似语句。</p>
<p>当一个跳转语句 (<code>break</code>, <code>continue</code>, <code>return</code> 和 <code>throw</code>) 强制控制流离开一个 <code>finally</code> 块时，这个规则就会产生一个问题。</p>
<h2>不合规的代码示例</h2>
<pre>
function foo() {
    try {
        return 1; // 期望返回1
    } catch(err) {
        return 2; // 或当有错误时返回2
    } finally {
        return 3; // 不合规: 3在1或2之前返回，这是我们没有预料到的
    }
}
</pre>
<h2>合规的解决方案</h2>
<pre>
function foo() {
    try {
        return 1; // 期望返回1
    } catch(err) {
        return 2; //  或当有错误时返回2
    }
}
</pre>
<h2>请参阅</h2>
<ul>
  <li> <a href="http://cwe.mitre.org/data/definitions/584.html">MITRE, CWE-584</a> - Return Inside Finally Block </li>
  <li> <a href="https://www.securecoding.cert.org/confluence/x/mIEbAQ">CERT, ERR04-J.</a> - Do not complete abruptly from a finally block </li>
</ul>

